[2025-07-12T13:24:03.571+0000] {local_task_job_runner.py:123} INFO - ::group::Pre task execution logs
[2025-07-12T13:24:03.592+0000] {taskinstance.py:2614} INFO - Dependencies all met for dep_context=non-requeueable deps ti=<TaskInstance: employee_ingestion_dag.send_alerts scheduled__2025-07-12T13:23:00+00:00 [queued]>
[2025-07-12T13:24:03.599+0000] {taskinstance.py:2614} INFO - Dependencies all met for dep_context=requeueable deps ti=<TaskInstance: employee_ingestion_dag.send_alerts scheduled__2025-07-12T13:23:00+00:00 [queued]>
[2025-07-12T13:24:03.599+0000] {taskinstance.py:2867} INFO - Starting attempt 1 of 1
[2025-07-12T13:24:03.611+0000] {taskinstance.py:2890} INFO - Executing <Task(_PythonDecoratedOperator): send_alerts> on 2025-07-12 13:23:00+00:00
[2025-07-12T13:24:03.619+0000] {warnings.py:112} WARNING - /home/airflow/.local/lib/python3.12/site-packages/airflow/task/task_runner/standard_task_runner.py:70: DeprecationWarning: This process (pid=515) is multi-threaded, use of fork() may lead to deadlocks in the child.
  pid = os.fork()

[2025-07-12T13:24:03.621+0000] {standard_task_runner.py:104} INFO - Running: ['airflow', 'tasks', 'run', 'employee_ingestion_dag', 'send_alerts', 'scheduled__2025-07-12T13:23:00+00:00', '--job-id', '117', '--raw', '--subdir', 'DAGS_FOLDER/ingestion_pipeline.py', '--cfg-path', '/tmp/tmpjupni38b']
[2025-07-12T13:24:03.622+0000] {standard_task_runner.py:72} INFO - Started process 518 to run task
[2025-07-12T13:24:03.622+0000] {standard_task_runner.py:105} INFO - Job 117: Subtask send_alerts
[2025-07-12T13:24:03.679+0000] {task_command.py:467} INFO - Running <TaskInstance: employee_ingestion_dag.send_alerts scheduled__2025-07-12T13:23:00+00:00 [running]> on host f80ef267dd5d
[2025-07-12T13:24:03.765+0000] {taskinstance.py:3134} INFO - Exporting env vars: AIRFLOW_CTX_DAG_OWNER='airflow' AIRFLOW_CTX_DAG_ID='employee_ingestion_dag' AIRFLOW_CTX_TASK_ID='send_alerts' AIRFLOW_CTX_EXECUTION_DATE='2025-07-12T13:23:00+00:00' AIRFLOW_CTX_TRY_NUMBER='1' AIRFLOW_CTX_DAG_RUN_ID='scheduled__2025-07-12T13:23:00+00:00'
[2025-07-12T13:24:03.766+0000] {taskinstance.py:732} INFO - ::endgroup::
[2025-07-12T13:24:06.355+0000] {ingestion_pipeline.py:113} WARNING - TEAMS_WEBHOOK_URL not configured, skipping Teams alert
[2025-07-12T13:24:06.376+0000] {ingestion_pipeline.py:130} WARNING - Failed to build data docs: [Errno 13] Permission denied: '/opt/airflow/gx/plugins/custom_data_docs/styles/data_docs_custom_styles.css'
[2025-07-12T13:24:06.376+0000] {ingestion_pipeline.py:178} ERROR - Alerting failed: 'filepath'
[2025-07-12T13:24:06.377+0000] {taskinstance.py:3313} ERROR - Task failed with exception
Traceback (most recent call last):
  File "/opt/airflow/dags/ingestion_pipeline.py", line 167, in send_alerts
    File: {os.path.basename(results['filepath'])}
                            ~~~~~~~^^^^^^^^^^^^
KeyError: 'filepath'

During handling of the above exception, another exception occurred:

Traceback (most recent call last):
  File "/home/airflow/.local/lib/python3.12/site-packages/airflow/models/taskinstance.py", line 768, in _execute_task
    result = _execute_callable(context=context, **execute_callable_kwargs)
             ^^^^^^^^^^^^^^^^^^^^^^^^^^^^^^^^^^^^^^^^^^^^^^^^^^^^^^^^^^^^^
  File "/home/airflow/.local/lib/python3.12/site-packages/airflow/models/taskinstance.py", line 734, in _execute_callable
    return ExecutionCallableRunner(
           ^^^^^^^^^^^^^^^^^^^^^^^^
  File "/home/airflow/.local/lib/python3.12/site-packages/airflow/utils/operator_helpers.py", line 252, in run
    return self.func(*args, **kwargs)
           ^^^^^^^^^^^^^^^^^^^^^^^^^^
  File "/home/airflow/.local/lib/python3.12/site-packages/airflow/models/baseoperator.py", line 424, in wrapper
    return func(self, *args, **kwargs)
           ^^^^^^^^^^^^^^^^^^^^^^^^^^^
  File "/home/airflow/.local/lib/python3.12/site-packages/airflow/decorators/base.py", line 266, in execute
    return_value = super().execute(context)
                   ^^^^^^^^^^^^^^^^^^^^^^^^
  File "/home/airflow/.local/lib/python3.12/site-packages/airflow/models/baseoperator.py", line 424, in wrapper
    return func(self, *args, **kwargs)
           ^^^^^^^^^^^^^^^^^^^^^^^^^^^
  File "/home/airflow/.local/lib/python3.12/site-packages/airflow/operators/python.py", line 238, in execute
    return_value = self.execute_callable()
                   ^^^^^^^^^^^^^^^^^^^^^^^
  File "/home/airflow/.local/lib/python3.12/site-packages/airflow/operators/python.py", line 256, in execute_callable
    return runner.run(*self.op_args, **self.op_kwargs)
           ^^^^^^^^^^^^^^^^^^^^^^^^^^^^^^^^^^^^^^^^^^^
  File "/home/airflow/.local/lib/python3.12/site-packages/airflow/utils/operator_helpers.py", line 252, in run
    return self.func(*args, **kwargs)
           ^^^^^^^^^^^^^^^^^^^^^^^^^^
  File "/opt/airflow/dags/ingestion_pipeline.py", line 180, in send_alerts
    logging.info(f"Validation completed for {os.path.basename(results['filepath'])}: {results['invalid_rows']}/{results['total_rows']} issues")
                                                              ~~~~~~~^^^^^^^^^^^^
KeyError: 'filepath'
[2025-07-12T13:24:06.391+0000] {taskinstance.py:1226} INFO - Marking task as FAILED. dag_id=employee_ingestion_dag, task_id=send_alerts, run_id=scheduled__2025-07-12T13:23:00+00:00, execution_date=20250712T132300, start_date=20250712T132403, end_date=20250712T132406
[2025-07-12T13:24:06.422+0000] {taskinstance.py:341} INFO - ::group::Post task execution logs
[2025-07-12T13:24:06.423+0000] {standard_task_runner.py:124} ERROR - Failed to execute job 117 for task send_alerts ('filepath'; 518)
Traceback (most recent call last):
  File "/opt/airflow/dags/ingestion_pipeline.py", line 167, in send_alerts
    File: {os.path.basename(results['filepath'])}
                            ~~~~~~~^^^^^^^^^^^^
KeyError: 'filepath'

During handling of the above exception, another exception occurred:

Traceback (most recent call last):
  File "/home/airflow/.local/lib/python3.12/site-packages/airflow/task/task_runner/standard_task_runner.py", line 117, in _start_by_fork
    ret = args.func(args, dag=self.dag)
          ^^^^^^^^^^^^^^^^^^^^^^^^^^^^^
  File "/home/airflow/.local/lib/python3.12/site-packages/airflow/cli/cli_config.py", line 49, in command
    return func(*args, **kwargs)
           ^^^^^^^^^^^^^^^^^^^^^
  File "/home/airflow/.local/lib/python3.12/site-packages/airflow/utils/cli.py", line 116, in wrapper
    return f(*args, **kwargs)
           ^^^^^^^^^^^^^^^^^^
  File "/home/airflow/.local/lib/python3.12/site-packages/airflow/cli/commands/task_command.py", line 483, in task_run
    task_return_code = _run_task_by_selected_method(args, _dag, ti)
                       ^^^^^^^^^^^^^^^^^^^^^^^^^^^^^^^^^^^^^^^^^^^^
  File "/home/airflow/.local/lib/python3.12/site-packages/airflow/cli/commands/task_command.py", line 256, in _run_task_by_selected_method
    return _run_raw_task(args, ti)
           ^^^^^^^^^^^^^^^^^^^^^^^
  File "/home/airflow/.local/lib/python3.12/site-packages/airflow/cli/commands/task_command.py", line 341, in _run_raw_task
    return ti._run_raw_task(
           ^^^^^^^^^^^^^^^^^
  File "/home/airflow/.local/lib/python3.12/site-packages/airflow/utils/session.py", line 97, in wrapper
    return func(*args, session=session, **kwargs)
           ^^^^^^^^^^^^^^^^^^^^^^^^^^^^^^^^^^^^^^
  File "/home/airflow/.local/lib/python3.12/site-packages/airflow/models/taskinstance.py", line 3006, in _run_raw_task
    return _run_raw_task(
           ^^^^^^^^^^^^^^
  File "/home/airflow/.local/lib/python3.12/site-packages/airflow/models/taskinstance.py", line 274, in _run_raw_task
    TaskInstance._execute_task_with_callbacks(
  File "/home/airflow/.local/lib/python3.12/site-packages/airflow/models/taskinstance.py", line 3161, in _execute_task_with_callbacks
    result = self._execute_task(context, task_orig)
             ^^^^^^^^^^^^^^^^^^^^^^^^^^^^^^^^^^^^^^
  File "/home/airflow/.local/lib/python3.12/site-packages/airflow/models/taskinstance.py", line 3185, in _execute_task
    return _execute_task(self, context, task_orig)
           ^^^^^^^^^^^^^^^^^^^^^^^^^^^^^^^^^^^^^^^
  File "/home/airflow/.local/lib/python3.12/site-packages/airflow/models/taskinstance.py", line 768, in _execute_task
    result = _execute_callable(context=context, **execute_callable_kwargs)
             ^^^^^^^^^^^^^^^^^^^^^^^^^^^^^^^^^^^^^^^^^^^^^^^^^^^^^^^^^^^^^
  File "/home/airflow/.local/lib/python3.12/site-packages/airflow/models/taskinstance.py", line 734, in _execute_callable
    return ExecutionCallableRunner(
           ^^^^^^^^^^^^^^^^^^^^^^^^
  File "/home/airflow/.local/lib/python3.12/site-packages/airflow/utils/operator_helpers.py", line 252, in run
    return self.func(*args, **kwargs)
           ^^^^^^^^^^^^^^^^^^^^^^^^^^
  File "/home/airflow/.local/lib/python3.12/site-packages/airflow/models/baseoperator.py", line 424, in wrapper
    return func(self, *args, **kwargs)
           ^^^^^^^^^^^^^^^^^^^^^^^^^^^
  File "/home/airflow/.local/lib/python3.12/site-packages/airflow/decorators/base.py", line 266, in execute
    return_value = super().execute(context)
                   ^^^^^^^^^^^^^^^^^^^^^^^^
  File "/home/airflow/.local/lib/python3.12/site-packages/airflow/models/baseoperator.py", line 424, in wrapper
    return func(self, *args, **kwargs)
           ^^^^^^^^^^^^^^^^^^^^^^^^^^^
  File "/home/airflow/.local/lib/python3.12/site-packages/airflow/operators/python.py", line 238, in execute
    return_value = self.execute_callable()
                   ^^^^^^^^^^^^^^^^^^^^^^^
  File "/home/airflow/.local/lib/python3.12/site-packages/airflow/operators/python.py", line 256, in execute_callable
    return runner.run(*self.op_args, **self.op_kwargs)
           ^^^^^^^^^^^^^^^^^^^^^^^^^^^^^^^^^^^^^^^^^^^
  File "/home/airflow/.local/lib/python3.12/site-packages/airflow/utils/operator_helpers.py", line 252, in run
    return self.func(*args, **kwargs)
           ^^^^^^^^^^^^^^^^^^^^^^^^^^
  File "/opt/airflow/dags/ingestion_pipeline.py", line 180, in send_alerts
    logging.info(f"Validation completed for {os.path.basename(results['filepath'])}: {results['invalid_rows']}/{results['total_rows']} issues")
                                                              ~~~~~~~^^^^^^^^^^^^
KeyError: 'filepath'
[2025-07-12T13:24:06.488+0000] {local_task_job_runner.py:266} INFO - Task exited with return code 1
[2025-07-12T13:24:06.508+0000] {taskinstance.py:3901} INFO - 0 downstream tasks scheduled from follow-on schedule check
[2025-07-12T13:24:06.510+0000] {local_task_job_runner.py:245} INFO - ::endgroup::
