[2025-07-11T12:01:45.732+0000] {local_task_job_runner.py:123} INFO - ::group::Pre task execution logs
[2025-07-11T12:01:45.763+0000] {taskinstance.py:2614} INFO - Dependencies all met for dep_context=non-requeueable deps ti=<TaskInstance: employee_ingestion_dag.validate_data scheduled__2025-07-11T12:00:00+00:00 [queued]>
[2025-07-11T12:01:45.779+0000] {taskinstance.py:2614} INFO - Dependencies all met for dep_context=requeueable deps ti=<TaskInstance: employee_ingestion_dag.validate_data scheduled__2025-07-11T12:00:00+00:00 [queued]>
[2025-07-11T12:01:45.780+0000] {taskinstance.py:2867} INFO - Starting attempt 1 of 1
[2025-07-11T12:01:45.802+0000] {taskinstance.py:2890} INFO - Executing <Task(_PythonDecoratedOperator): validate_data> on 2025-07-11 12:00:00+00:00
[2025-07-11T12:01:45.812+0000] {warnings.py:112} WARNING - /home/airflow/.local/lib/python3.12/site-packages/airflow/task/task_runner/standard_task_runner.py:70: DeprecationWarning: This process (pid=113) is multi-threaded, use of fork() may lead to deadlocks in the child.
  pid = os.fork()

[2025-07-11T12:01:45.814+0000] {standard_task_runner.py:72} INFO - Started process 114 to run task
[2025-07-11T12:01:45.814+0000] {standard_task_runner.py:104} INFO - Running: ['airflow', 'tasks', 'run', 'employee_ingestion_dag', 'validate_data', 'scheduled__2025-07-11T12:00:00+00:00', '--job-id', '9', '--raw', '--subdir', 'DAGS_FOLDER/ingestion_pipeline.py', '--cfg-path', '/tmp/tmp4io5spjj']
[2025-07-11T12:01:45.815+0000] {standard_task_runner.py:105} INFO - Job 9: Subtask validate_data
[2025-07-11T12:01:45.888+0000] {task_command.py:467} INFO - Running <TaskInstance: employee_ingestion_dag.validate_data scheduled__2025-07-11T12:00:00+00:00 [running]> on host 5a07e0ddeb4c
[2025-07-11T12:01:46.014+0000] {taskinstance.py:3134} INFO - Exporting env vars: AIRFLOW_CTX_DAG_OWNER='airflow' AIRFLOW_CTX_DAG_ID='employee_ingestion_dag' AIRFLOW_CTX_TASK_ID='validate_data' AIRFLOW_CTX_EXECUTION_DATE='2025-07-11T12:00:00+00:00' AIRFLOW_CTX_TRY_NUMBER='1' AIRFLOW_CTX_DAG_RUN_ID='scheduled__2025-07-11T12:00:00+00:00'
[2025-07-11T12:01:46.019+0000] {taskinstance.py:732} INFO - ::endgroup::
[2025-07-11T12:01:49.199+0000] {warnings.py:112} WARNING - /home/airflow/.local/lib/python3.12/site-packages/great_expectations/data_context/data_context/serializable_data_context.py:225: UserWarning: Warning. An existing `great_expectations.yml` was found here: /opt/airflow/gx.
    - No action was taken.
  warnings.warn(message)

[2025-07-11T12:01:49.200+0000] {warnings.py:112} WARNING - /home/airflow/.local/lib/python3.12/site-packages/great_expectations/data_context/data_context/serializable_data_context.py:233: UserWarning: Warning. An existing `config_variables.yml` was found here: /opt/airflow/gx/uncommitted.
    - No action was taken.
  warnings.warn(message)

[2025-07-11T12:01:49.230+0000] {file_data_context.py:222} INFO - FileDataContext loading fluent config
[2025-07-11T12:01:49.241+0000] {config.py:187} INFO - Loading 'datasources' ->
[{'assets': [...], 'name': 'employee_datasource', 'type': 'pandas'}]
[2025-07-11T12:01:49.241+0000] {fluent_base_model.py:276} INFO - _PandasDataAsset.dict() - missing `config_provider`, skipping config substitution
[2025-07-11T12:01:49.382+0000] {abstract_data_context.py:5516} INFO - Loaded 'employee_datasource' from fluent config
[2025-07-11T12:01:49.446+0000] {file_data_context.py:174} INFO - Saving 1 Fluent Datasources to /opt/airflow/great_expectations/great_expectations.yml
[2025-07-11T12:01:49.447+0000] {fluent_base_model.py:276} INFO - PandasDatasource.dict() - missing `config_provider`, skipping config substitution
[2025-07-11T12:01:49.472+0000] {file_data_context.py:174} INFO - Saving 1 Fluent Datasources to /opt/airflow/great_expectations/great_expectations.yml
[2025-07-11T12:01:49.473+0000] {fluent_base_model.py:276} INFO - CSVAsset.dict() - missing `config_provider`, skipping config substitution
[2025-07-11T12:01:49.473+0000] {fluent_base_model.py:276} INFO - PandasDatasource.dict() - missing `config_provider`, skipping config substitution
[2025-07-11T12:01:49.495+0000] {taskinstance.py:3313} ERROR - Task failed with exception
Traceback (most recent call last):
  File "/opt/airflow/dags/ingestion_pipeline.py", line 62, in validate_data
    suite = context.get_expectation_suite(SUITE_NAME)
            ^^^^^^^^^^^^^^^^^^^^^^^^^^^^^^^^^^^^^^^^^
  File "/home/airflow/.local/lib/python3.12/site-packages/great_expectations/data_context/data_context/abstract_data_context.py", line 3035, in get_expectation_suite
    raise gx_exceptions.DataContextError(
great_expectations.exceptions.exceptions.DataContextError: expectation_suite employee_data_suite not found

During handling of the above exception, another exception occurred:

Traceback (most recent call last):
  File "/home/airflow/.local/lib/python3.12/site-packages/airflow/models/taskinstance.py", line 768, in _execute_task
    result = _execute_callable(context=context, **execute_callable_kwargs)
             ^^^^^^^^^^^^^^^^^^^^^^^^^^^^^^^^^^^^^^^^^^^^^^^^^^^^^^^^^^^^^
  File "/home/airflow/.local/lib/python3.12/site-packages/airflow/models/taskinstance.py", line 734, in _execute_callable
    return ExecutionCallableRunner(
           ^^^^^^^^^^^^^^^^^^^^^^^^
  File "/home/airflow/.local/lib/python3.12/site-packages/airflow/utils/operator_helpers.py", line 252, in run
    return self.func(*args, **kwargs)
           ^^^^^^^^^^^^^^^^^^^^^^^^^^
  File "/home/airflow/.local/lib/python3.12/site-packages/airflow/models/baseoperator.py", line 424, in wrapper
    return func(self, *args, **kwargs)
           ^^^^^^^^^^^^^^^^^^^^^^^^^^^
  File "/home/airflow/.local/lib/python3.12/site-packages/airflow/decorators/base.py", line 266, in execute
    return_value = super().execute(context)
                   ^^^^^^^^^^^^^^^^^^^^^^^^
  File "/home/airflow/.local/lib/python3.12/site-packages/airflow/models/baseoperator.py", line 424, in wrapper
    return func(self, *args, **kwargs)
           ^^^^^^^^^^^^^^^^^^^^^^^^^^^
  File "/home/airflow/.local/lib/python3.12/site-packages/airflow/operators/python.py", line 238, in execute
    return_value = self.execute_callable()
                   ^^^^^^^^^^^^^^^^^^^^^^^
  File "/home/airflow/.local/lib/python3.12/site-packages/airflow/operators/python.py", line 256, in execute_callable
    return runner.run(*self.op_args, **self.op_kwargs)
           ^^^^^^^^^^^^^^^^^^^^^^^^^^^^^^^^^^^^^^^^^^^
  File "/home/airflow/.local/lib/python3.12/site-packages/airflow/utils/operator_helpers.py", line 252, in run
    return self.func(*args, **kwargs)
           ^^^^^^^^^^^^^^^^^^^^^^^^^^
  File "/opt/airflow/dags/ingestion_pipeline.py", line 71, in validate_data
    raise AirflowFailException(f"Validation failed: {str(e)}")
airflow.exceptions.AirflowFailException: Validation failed: expectation_suite employee_data_suite not found
[2025-07-11T12:01:49.514+0000] {taskinstance.py:1226} INFO - Immediate failure requested. Marking task as FAILED. dag_id=employee_ingestion_dag, task_id=validate_data, run_id=scheduled__2025-07-11T12:00:00+00:00, execution_date=20250711T120000, start_date=20250711T120145, end_date=20250711T120149
[2025-07-11T12:01:49.540+0000] {taskinstance.py:341} INFO - ::group::Post task execution logs
[2025-07-11T12:01:49.541+0000] {standard_task_runner.py:124} ERROR - Failed to execute job 9 for task validate_data (Validation failed: expectation_suite employee_data_suite not found; 114)
Traceback (most recent call last):
  File "/opt/airflow/dags/ingestion_pipeline.py", line 62, in validate_data
    suite = context.get_expectation_suite(SUITE_NAME)
            ^^^^^^^^^^^^^^^^^^^^^^^^^^^^^^^^^^^^^^^^^
  File "/home/airflow/.local/lib/python3.12/site-packages/great_expectations/data_context/data_context/abstract_data_context.py", line 3035, in get_expectation_suite
    raise gx_exceptions.DataContextError(
great_expectations.exceptions.exceptions.DataContextError: expectation_suite employee_data_suite not found

During handling of the above exception, another exception occurred:

Traceback (most recent call last):
  File "/home/airflow/.local/lib/python3.12/site-packages/airflow/task/task_runner/standard_task_runner.py", line 117, in _start_by_fork
    ret = args.func(args, dag=self.dag)
          ^^^^^^^^^^^^^^^^^^^^^^^^^^^^^
  File "/home/airflow/.local/lib/python3.12/site-packages/airflow/cli/cli_config.py", line 49, in command
    return func(*args, **kwargs)
           ^^^^^^^^^^^^^^^^^^^^^
  File "/home/airflow/.local/lib/python3.12/site-packages/airflow/utils/cli.py", line 116, in wrapper
    return f(*args, **kwargs)
           ^^^^^^^^^^^^^^^^^^
  File "/home/airflow/.local/lib/python3.12/site-packages/airflow/cli/commands/task_command.py", line 483, in task_run
    task_return_code = _run_task_by_selected_method(args, _dag, ti)
                       ^^^^^^^^^^^^^^^^^^^^^^^^^^^^^^^^^^^^^^^^^^^^
  File "/home/airflow/.local/lib/python3.12/site-packages/airflow/cli/commands/task_command.py", line 256, in _run_task_by_selected_method
    return _run_raw_task(args, ti)
           ^^^^^^^^^^^^^^^^^^^^^^^
  File "/home/airflow/.local/lib/python3.12/site-packages/airflow/cli/commands/task_command.py", line 341, in _run_raw_task
    return ti._run_raw_task(
           ^^^^^^^^^^^^^^^^^
  File "/home/airflow/.local/lib/python3.12/site-packages/airflow/utils/session.py", line 97, in wrapper
    return func(*args, session=session, **kwargs)
           ^^^^^^^^^^^^^^^^^^^^^^^^^^^^^^^^^^^^^^
  File "/home/airflow/.local/lib/python3.12/site-packages/airflow/models/taskinstance.py", line 3006, in _run_raw_task
    return _run_raw_task(
           ^^^^^^^^^^^^^^
  File "/home/airflow/.local/lib/python3.12/site-packages/airflow/models/taskinstance.py", line 274, in _run_raw_task
    TaskInstance._execute_task_with_callbacks(
  File "/home/airflow/.local/lib/python3.12/site-packages/airflow/models/taskinstance.py", line 3161, in _execute_task_with_callbacks
    result = self._execute_task(context, task_orig)
             ^^^^^^^^^^^^^^^^^^^^^^^^^^^^^^^^^^^^^^
  File "/home/airflow/.local/lib/python3.12/site-packages/airflow/models/taskinstance.py", line 3185, in _execute_task
    return _execute_task(self, context, task_orig)
           ^^^^^^^^^^^^^^^^^^^^^^^^^^^^^^^^^^^^^^^
  File "/home/airflow/.local/lib/python3.12/site-packages/airflow/models/taskinstance.py", line 768, in _execute_task
    result = _execute_callable(context=context, **execute_callable_kwargs)
             ^^^^^^^^^^^^^^^^^^^^^^^^^^^^^^^^^^^^^^^^^^^^^^^^^^^^^^^^^^^^^
  File "/home/airflow/.local/lib/python3.12/site-packages/airflow/models/taskinstance.py", line 734, in _execute_callable
    return ExecutionCallableRunner(
           ^^^^^^^^^^^^^^^^^^^^^^^^
  File "/home/airflow/.local/lib/python3.12/site-packages/airflow/utils/operator_helpers.py", line 252, in run
    return self.func(*args, **kwargs)
           ^^^^^^^^^^^^^^^^^^^^^^^^^^
  File "/home/airflow/.local/lib/python3.12/site-packages/airflow/models/baseoperator.py", line 424, in wrapper
    return func(self, *args, **kwargs)
           ^^^^^^^^^^^^^^^^^^^^^^^^^^^
  File "/home/airflow/.local/lib/python3.12/site-packages/airflow/decorators/base.py", line 266, in execute
    return_value = super().execute(context)
                   ^^^^^^^^^^^^^^^^^^^^^^^^
  File "/home/airflow/.local/lib/python3.12/site-packages/airflow/models/baseoperator.py", line 424, in wrapper
    return func(self, *args, **kwargs)
           ^^^^^^^^^^^^^^^^^^^^^^^^^^^
  File "/home/airflow/.local/lib/python3.12/site-packages/airflow/operators/python.py", line 238, in execute
    return_value = self.execute_callable()
                   ^^^^^^^^^^^^^^^^^^^^^^^
  File "/home/airflow/.local/lib/python3.12/site-packages/airflow/operators/python.py", line 256, in execute_callable
    return runner.run(*self.op_args, **self.op_kwargs)
           ^^^^^^^^^^^^^^^^^^^^^^^^^^^^^^^^^^^^^^^^^^^
  File "/home/airflow/.local/lib/python3.12/site-packages/airflow/utils/operator_helpers.py", line 252, in run
    return self.func(*args, **kwargs)
           ^^^^^^^^^^^^^^^^^^^^^^^^^^
  File "/opt/airflow/dags/ingestion_pipeline.py", line 71, in validate_data
    raise AirflowFailException(f"Validation failed: {str(e)}")
airflow.exceptions.AirflowFailException: Validation failed: expectation_suite employee_data_suite not found
[2025-07-11T12:01:49.611+0000] {local_task_job_runner.py:266} INFO - Task exited with return code 1
[2025-07-11T12:01:49.629+0000] {taskinstance.py:3901} INFO - 0 downstream tasks scheduled from follow-on schedule check
[2025-07-11T12:01:49.639+0000] {local_task_job_runner.py:245} INFO - ::endgroup::
