[2025-07-13T10:50:02.147+0000] {local_task_job_runner.py:123} INFO - ::group::Pre task execution logs
[2025-07-13T10:50:02.167+0000] {taskinstance.py:2614} INFO - Dependencies all met for dep_context=non-requeueable deps ti=<TaskInstance: employee_prediction_job.check_for_new_data scheduled__2025-07-13T10:45:00+00:00 [queued]>
[2025-07-13T10:50:02.174+0000] {taskinstance.py:2614} INFO - Dependencies all met for dep_context=requeueable deps ti=<TaskInstance: employee_prediction_job.check_for_new_data scheduled__2025-07-13T10:45:00+00:00 [queued]>
[2025-07-13T10:50:02.175+0000] {taskinstance.py:2867} INFO - Starting attempt 1 of 1
[2025-07-13T10:50:02.187+0000] {taskinstance.py:2890} INFO - Executing <Task(PythonOperator): check_for_new_data> on 2025-07-13 10:45:00+00:00
[2025-07-13T10:50:02.194+0000] {warnings.py:112} WARNING - /home/airflow/.local/lib/python3.12/site-packages/airflow/task/task_runner/standard_task_runner.py:70: DeprecationWarning: This process (pid=61) is multi-threaded, use of fork() may lead to deadlocks in the child.
  pid = os.fork()

[2025-07-13T10:50:02.195+0000] {standard_task_runner.py:72} INFO - Started process 65 to run task
[2025-07-13T10:50:02.196+0000] {standard_task_runner.py:104} INFO - Running: ['airflow', 'tasks', 'run', 'employee_prediction_job', 'check_for_new_data', 'scheduled__2025-07-13T10:45:00+00:00', '--job-id', '92', '--raw', '--subdir', 'DAGS_FOLDER/prediction_job.py', '--cfg-path', '/tmp/tmpjbkmg695']
[2025-07-13T10:50:02.198+0000] {standard_task_runner.py:105} INFO - Job 92: Subtask check_for_new_data
[2025-07-13T10:50:02.259+0000] {task_command.py:467} INFO - Running <TaskInstance: employee_prediction_job.check_for_new_data scheduled__2025-07-13T10:45:00+00:00 [running]> on host c45a93548ada
[2025-07-13T10:50:02.588+0000] {taskinstance.py:3134} INFO - Exporting env vars: AIRFLOW_CTX_DAG_OWNER='airflow' AIRFLOW_CTX_DAG_ID='employee_prediction_job' AIRFLOW_CTX_TASK_ID='check_for_new_data' AIRFLOW_CTX_EXECUTION_DATE='2025-07-13T10:45:00+00:00' AIRFLOW_CTX_TRY_NUMBER='1' AIRFLOW_CTX_DAG_RUN_ID='scheduled__2025-07-13T10:45:00+00:00'
[2025-07-13T10:50:02.590+0000] {taskinstance.py:732} INFO - ::endgroup::
[2025-07-13T10:50:02.619+0000] {crypto.py:82} WARNING - empty cryptography key - values will not be stored encrypted.
[2025-07-13T10:50:02.625+0000] {base.py:84} INFO - Retrieving connection 'processed_files_db'
[2025-07-13T10:50:02.640+0000] {taskinstance.py:3313} ERROR - Task failed with exception
Traceback (most recent call last):
  File "/home/airflow/.local/lib/python3.12/site-packages/airflow/models/taskinstance.py", line 768, in _execute_task
    result = _execute_callable(context=context, **execute_callable_kwargs)
             ^^^^^^^^^^^^^^^^^^^^^^^^^^^^^^^^^^^^^^^^^^^^^^^^^^^^^^^^^^^^^
  File "/home/airflow/.local/lib/python3.12/site-packages/airflow/models/taskinstance.py", line 734, in _execute_callable
    return ExecutionCallableRunner(
           ^^^^^^^^^^^^^^^^^^^^^^^^
  File "/home/airflow/.local/lib/python3.12/site-packages/airflow/utils/operator_helpers.py", line 252, in run
    return self.func(*args, **kwargs)
           ^^^^^^^^^^^^^^^^^^^^^^^^^^
  File "/home/airflow/.local/lib/python3.12/site-packages/airflow/models/baseoperator.py", line 424, in wrapper
    return func(self, *args, **kwargs)
           ^^^^^^^^^^^^^^^^^^^^^^^^^^^
  File "/home/airflow/.local/lib/python3.12/site-packages/airflow/operators/python.py", line 238, in execute
    return_value = self.execute_callable()
                   ^^^^^^^^^^^^^^^^^^^^^^^
  File "/home/airflow/.local/lib/python3.12/site-packages/airflow/operators/python.py", line 256, in execute_callable
    return runner.run(*self.op_args, **self.op_kwargs)
           ^^^^^^^^^^^^^^^^^^^^^^^^^^^^^^^^^^^^^^^^^^^
  File "/home/airflow/.local/lib/python3.12/site-packages/airflow/utils/operator_helpers.py", line 252, in run
    return self.func(*args, **kwargs)
           ^^^^^^^^^^^^^^^^^^^^^^^^^^
  File "/opt/airflow/dags/prediction_job.py", line 27, in check_for_new_data
    processed_files = get_processed_files()
                      ^^^^^^^^^^^^^^^^^^^^^
  File "/opt/airflow/dags/prediction_job.py", line 17, in get_processed_files
    cursor.execute("SELECT file_name FROM processed_files;")
psycopg2.errors.UndefinedTable: relation "processed_files" does not exist
LINE 1: SELECT file_name FROM processed_files;
                              ^

[2025-07-13T10:50:02.667+0000] {taskinstance.py:1226} INFO - Marking task as FAILED. dag_id=employee_prediction_job, task_id=check_for_new_data, run_id=scheduled__2025-07-13T10:45:00+00:00, execution_date=20250713T104500, start_date=20250713T105002, end_date=20250713T105002
[2025-07-13T10:50:02.704+0000] {taskinstance.py:341} INFO - ::group::Post task execution logs
[2025-07-13T10:50:02.705+0000] {standard_task_runner.py:124} ERROR - Failed to execute job 92 for task check_for_new_data (relation "processed_files" does not exist
LINE 1: SELECT file_name FROM processed_files;
                              ^
; 65)
Traceback (most recent call last):
  File "/home/airflow/.local/lib/python3.12/site-packages/airflow/task/task_runner/standard_task_runner.py", line 117, in _start_by_fork
    ret = args.func(args, dag=self.dag)
          ^^^^^^^^^^^^^^^^^^^^^^^^^^^^^
  File "/home/airflow/.local/lib/python3.12/site-packages/airflow/cli/cli_config.py", line 49, in command
    return func(*args, **kwargs)
           ^^^^^^^^^^^^^^^^^^^^^
  File "/home/airflow/.local/lib/python3.12/site-packages/airflow/utils/cli.py", line 116, in wrapper
    return f(*args, **kwargs)
           ^^^^^^^^^^^^^^^^^^
  File "/home/airflow/.local/lib/python3.12/site-packages/airflow/cli/commands/task_command.py", line 483, in task_run
    task_return_code = _run_task_by_selected_method(args, _dag, ti)
                       ^^^^^^^^^^^^^^^^^^^^^^^^^^^^^^^^^^^^^^^^^^^^
  File "/home/airflow/.local/lib/python3.12/site-packages/airflow/cli/commands/task_command.py", line 256, in _run_task_by_selected_method
    return _run_raw_task(args, ti)
           ^^^^^^^^^^^^^^^^^^^^^^^
  File "/home/airflow/.local/lib/python3.12/site-packages/airflow/cli/commands/task_command.py", line 341, in _run_raw_task
    return ti._run_raw_task(
           ^^^^^^^^^^^^^^^^^
  File "/home/airflow/.local/lib/python3.12/site-packages/airflow/utils/session.py", line 97, in wrapper
    return func(*args, session=session, **kwargs)
           ^^^^^^^^^^^^^^^^^^^^^^^^^^^^^^^^^^^^^^
  File "/home/airflow/.local/lib/python3.12/site-packages/airflow/models/taskinstance.py", line 3006, in _run_raw_task
    return _run_raw_task(
           ^^^^^^^^^^^^^^
  File "/home/airflow/.local/lib/python3.12/site-packages/airflow/models/taskinstance.py", line 274, in _run_raw_task
    TaskInstance._execute_task_with_callbacks(
  File "/home/airflow/.local/lib/python3.12/site-packages/airflow/models/taskinstance.py", line 3161, in _execute_task_with_callbacks
    result = self._execute_task(context, task_orig)
             ^^^^^^^^^^^^^^^^^^^^^^^^^^^^^^^^^^^^^^
  File "/home/airflow/.local/lib/python3.12/site-packages/airflow/models/taskinstance.py", line 3185, in _execute_task
    return _execute_task(self, context, task_orig)
           ^^^^^^^^^^^^^^^^^^^^^^^^^^^^^^^^^^^^^^^
  File "/home/airflow/.local/lib/python3.12/site-packages/airflow/models/taskinstance.py", line 768, in _execute_task
    result = _execute_callable(context=context, **execute_callable_kwargs)
             ^^^^^^^^^^^^^^^^^^^^^^^^^^^^^^^^^^^^^^^^^^^^^^^^^^^^^^^^^^^^^
  File "/home/airflow/.local/lib/python3.12/site-packages/airflow/models/taskinstance.py", line 734, in _execute_callable
    return ExecutionCallableRunner(
           ^^^^^^^^^^^^^^^^^^^^^^^^
  File "/home/airflow/.local/lib/python3.12/site-packages/airflow/utils/operator_helpers.py", line 252, in run
    return self.func(*args, **kwargs)
           ^^^^^^^^^^^^^^^^^^^^^^^^^^
  File "/home/airflow/.local/lib/python3.12/site-packages/airflow/models/baseoperator.py", line 424, in wrapper
    return func(self, *args, **kwargs)
           ^^^^^^^^^^^^^^^^^^^^^^^^^^^
  File "/home/airflow/.local/lib/python3.12/site-packages/airflow/operators/python.py", line 238, in execute
    return_value = self.execute_callable()
                   ^^^^^^^^^^^^^^^^^^^^^^^
  File "/home/airflow/.local/lib/python3.12/site-packages/airflow/operators/python.py", line 256, in execute_callable
    return runner.run(*self.op_args, **self.op_kwargs)
           ^^^^^^^^^^^^^^^^^^^^^^^^^^^^^^^^^^^^^^^^^^^
  File "/home/airflow/.local/lib/python3.12/site-packages/airflow/utils/operator_helpers.py", line 252, in run
    return self.func(*args, **kwargs)
           ^^^^^^^^^^^^^^^^^^^^^^^^^^
  File "/opt/airflow/dags/prediction_job.py", line 27, in check_for_new_data
    processed_files = get_processed_files()
                      ^^^^^^^^^^^^^^^^^^^^^
  File "/opt/airflow/dags/prediction_job.py", line 17, in get_processed_files
    cursor.execute("SELECT file_name FROM processed_files;")
psycopg2.errors.UndefinedTable: relation "processed_files" does not exist
LINE 1: SELECT file_name FROM processed_files;
                              ^

[2025-07-13T10:50:02.731+0000] {local_task_job_runner.py:266} INFO - Task exited with return code 1
[2025-07-13T10:50:02.925+0000] {taskinstance.py:3901} INFO - 0 downstream tasks scheduled from follow-on schedule check
[2025-07-13T10:50:02.928+0000] {local_task_job_runner.py:245} INFO - ::endgroup::
