[2025-07-12T13:18:19.353+0000] {local_task_job_runner.py:123} INFO - ::group::Pre task execution logs
[2025-07-12T13:18:19.375+0000] {taskinstance.py:2614} INFO - Dependencies all met for dep_context=non-requeueable deps ti=<TaskInstance: employee_ingestion_dag.validate_data __airflow_temporary_run_2025-07-12T13:18:17.379808+00:00__ [queued]>
[2025-07-12T13:18:19.385+0000] {taskinstance.py:2614} INFO - Dependencies all met for dep_context=requeueable deps ti=<TaskInstance: employee_ingestion_dag.validate_data __airflow_temporary_run_2025-07-12T13:18:17.379808+00:00__ [queued]>
[2025-07-12T13:18:19.386+0000] {taskinstance.py:2867} INFO - Starting attempt 1 of 1
[2025-07-12T13:18:19.397+0000] {taskinstance.py:2890} INFO - Executing <Task(_PythonDecoratedOperator): validate_data> on 2025-07-12 00:00:00+00:00
[2025-07-12T13:18:19.404+0000] {warnings.py:112} WARNING - /home/airflow/.local/lib/python3.12/site-packages/airflow/task/task_runner/standard_task_runner.py:70: DeprecationWarning: This process (pid=283) is multi-threaded, use of fork() may lead to deadlocks in the child.
  pid = os.fork()

[2025-07-12T13:18:19.406+0000] {standard_task_runner.py:72} INFO - Started process 284 to run task
[2025-07-12T13:18:19.406+0000] {standard_task_runner.py:104} INFO - Running: ['airflow', 'tasks', 'run', 'employee_ingestion_dag', 'validate_data', '__airflow_temporary_run_2025-07-12T13:18:17.379808+00:00__', '--job-id', '81', '--raw', '--subdir', 'DAGS_FOLDER/ingestion_pipeline.py', '--cfg-path', '/tmp/tmpzlwk5w2f']
[2025-07-12T13:18:19.407+0000] {standard_task_runner.py:105} INFO - Job 81: Subtask validate_data
[2025-07-12T13:18:19.467+0000] {task_command.py:467} INFO - Running <TaskInstance: employee_ingestion_dag.validate_data __airflow_temporary_run_2025-07-12T13:18:17.379808+00:00__ [running]> on host f80ef267dd5d
[2025-07-12T13:18:19.577+0000] {taskinstance.py:3134} INFO - Exporting env vars: AIRFLOW_CTX_DAG_OWNER='airflow' AIRFLOW_CTX_DAG_ID='employee_ingestion_dag' AIRFLOW_CTX_TASK_ID='validate_data' AIRFLOW_CTX_EXECUTION_DATE='2025-07-12T00:00:00+00:00' AIRFLOW_CTX_TRY_NUMBER='1' AIRFLOW_CTX_DAG_RUN_ID='__airflow_temporary_run_2025-07-12T13:18:17.379808+00:00__'
[2025-07-12T13:18:19.579+0000] {taskinstance.py:732} INFO - ::endgroup::
[2025-07-12T13:18:22.140+0000] {taskinstance.py:3313} ERROR - Task failed with exception
Traceback (most recent call last):
  File "/opt/airflow/dags/ingestion_pipeline.py", line 41, in validate_data
    context = gx.get_context(context_root_dir=GE_DATA_CONTEXT_ROOT)
              ^^^^^^^^^^^^^^^^^^^^^^^^^^^^^^^^^^^^^^^^^^^^^^^^^^^^^
  File "/home/airflow/.local/lib/python3.12/site-packages/great_expectations/data_context/data_context/context_factory.py", line 263, in get_context
    context = _get_context(**kwargs)
              ^^^^^^^^^^^^^^^^^^^^^^
  File "/home/airflow/.local/lib/python3.12/site-packages/great_expectations/data_context/data_context/context_factory.py", line 302, in _get_context
    file_context = _get_file_context(
                   ^^^^^^^^^^^^^^^^^^
  File "/home/airflow/.local/lib/python3.12/site-packages/great_expectations/data_context/data_context/context_factory.py", line 383, in _get_file_context
    return FileDataContext(
           ^^^^^^^^^^^^^^^^
  File "/home/airflow/.local/lib/python3.12/site-packages/great_expectations/data_context/data_context/file_data_context.py", line 64, in __init__
    self._scaffold_project()
  File "/home/airflow/.local/lib/python3.12/site-packages/great_expectations/data_context/data_context/file_data_context.py", line 98, in _scaffold_project
    self._scaffold(
  File "/home/airflow/.local/lib/python3.12/site-packages/great_expectations/data_context/data_context/serializable_data_context.py", line 220, in _scaffold
    cls._scaffold_directories(gx_dir)
  File "/home/airflow/.local/lib/python3.12/site-packages/great_expectations/data_context/data_context/serializable_data_context.py", line 316, in _scaffold_directories
    cls._scaffold_custom_data_docs(plugins_dir)
  File "/home/airflow/.local/lib/python3.12/site-packages/great_expectations/data_context/data_context/serializable_data_context.py", line 351, in _scaffold_custom_data_docs
    shutil.copyfile(styles_template, styles_destination_path)
  File "/usr/local/lib/python3.12/shutil.py", line 262, in copyfile
    with open(dst, 'wb') as fdst:
         ^^^^^^^^^^^^^^^
PermissionError: [Errno 13] Permission denied: '/opt/airflow/gx/plugins/custom_data_docs/styles/data_docs_custom_styles.css'

During handling of the above exception, another exception occurred:

Traceback (most recent call last):
  File "/home/airflow/.local/lib/python3.12/site-packages/airflow/models/taskinstance.py", line 768, in _execute_task
    result = _execute_callable(context=context, **execute_callable_kwargs)
             ^^^^^^^^^^^^^^^^^^^^^^^^^^^^^^^^^^^^^^^^^^^^^^^^^^^^^^^^^^^^^
  File "/home/airflow/.local/lib/python3.12/site-packages/airflow/models/taskinstance.py", line 734, in _execute_callable
    return ExecutionCallableRunner(
           ^^^^^^^^^^^^^^^^^^^^^^^^
  File "/home/airflow/.local/lib/python3.12/site-packages/airflow/utils/operator_helpers.py", line 252, in run
    return self.func(*args, **kwargs)
           ^^^^^^^^^^^^^^^^^^^^^^^^^^
  File "/home/airflow/.local/lib/python3.12/site-packages/airflow/models/baseoperator.py", line 424, in wrapper
    return func(self, *args, **kwargs)
           ^^^^^^^^^^^^^^^^^^^^^^^^^^^
  File "/home/airflow/.local/lib/python3.12/site-packages/airflow/decorators/base.py", line 266, in execute
    return_value = super().execute(context)
                   ^^^^^^^^^^^^^^^^^^^^^^^^
  File "/home/airflow/.local/lib/python3.12/site-packages/airflow/models/baseoperator.py", line 424, in wrapper
    return func(self, *args, **kwargs)
           ^^^^^^^^^^^^^^^^^^^^^^^^^^^
  File "/home/airflow/.local/lib/python3.12/site-packages/airflow/operators/python.py", line 238, in execute
    return_value = self.execute_callable()
                   ^^^^^^^^^^^^^^^^^^^^^^^
  File "/home/airflow/.local/lib/python3.12/site-packages/airflow/operators/python.py", line 256, in execute_callable
    return runner.run(*self.op_args, **self.op_kwargs)
           ^^^^^^^^^^^^^^^^^^^^^^^^^^^^^^^^^^^^^^^^^^^
  File "/home/airflow/.local/lib/python3.12/site-packages/airflow/utils/operator_helpers.py", line 252, in run
    return self.func(*args, **kwargs)
           ^^^^^^^^^^^^^^^^^^^^^^^^^^
  File "/opt/airflow/dags/ingestion_pipeline.py", line 71, in validate_data
    raise AirflowFailException(f"Validation failed: {str(e)}")
airflow.exceptions.AirflowFailException: Validation failed: [Errno 13] Permission denied: '/opt/airflow/gx/plugins/custom_data_docs/styles/data_docs_custom_styles.css'
[2025-07-12T13:18:22.155+0000] {taskinstance.py:1226} INFO - Immediate failure requested. Marking task as FAILED. dag_id=employee_ingestion_dag, task_id=validate_data, run_id=__airflow_temporary_run_2025-07-12T13:18:17.379808+00:00__, execution_date=20250712T000000, start_date=20250712T131819, end_date=20250712T131822
[2025-07-12T13:18:22.162+0000] {taskinstance.py:341} INFO - ::group::Post task execution logs
[2025-07-12T13:18:22.162+0000] {standard_task_runner.py:124} ERROR - Failed to execute job 81 for task validate_data ((psycopg2.errors.ForeignKeyViolation) insert or update on table "task_fail" violates foreign key constraint "task_fail_ti_fkey"
DETAIL:  Key (dag_id, task_id, run_id, map_index)=(employee_ingestion_dag, validate_data, __airflow_temporary_run_2025-07-12T13:18:17.379808+00:00__, -1) is not present in table "task_instance".

[SQL: INSERT INTO task_fail (task_id, dag_id, run_id, map_index, start_date, end_date, duration) VALUES (%(task_id)s, %(dag_id)s, %(run_id)s, %(map_index)s, %(start_date)s, %(end_date)s, %(duration)s) RETURNING task_fail.id]
[parameters: {'task_id': 'validate_data', 'dag_id': 'employee_ingestion_dag', 'run_id': '__airflow_temporary_run_2025-07-12T13:18:17.379808+00:00__', 'map_index': -1, 'start_date': datetime.datetime(2025, 7, 12, 13, 18, 19, 377418, tzinfo=Timezone('UTC')), 'end_date': datetime.datetime(2025, 7, 12, 13, 18, 22, 155373, tzinfo=Timezone('UTC')), 'duration': 2}]
(Background on this error at: https://sqlalche.me/e/14/gkpj); 284)
Traceback (most recent call last):
  File "/opt/airflow/dags/ingestion_pipeline.py", line 41, in validate_data
    context = gx.get_context(context_root_dir=GE_DATA_CONTEXT_ROOT)
              ^^^^^^^^^^^^^^^^^^^^^^^^^^^^^^^^^^^^^^^^^^^^^^^^^^^^^
  File "/home/airflow/.local/lib/python3.12/site-packages/great_expectations/data_context/data_context/context_factory.py", line 263, in get_context
    context = _get_context(**kwargs)
              ^^^^^^^^^^^^^^^^^^^^^^
  File "/home/airflow/.local/lib/python3.12/site-packages/great_expectations/data_context/data_context/context_factory.py", line 302, in _get_context
    file_context = _get_file_context(
                   ^^^^^^^^^^^^^^^^^^
  File "/home/airflow/.local/lib/python3.12/site-packages/great_expectations/data_context/data_context/context_factory.py", line 383, in _get_file_context
    return FileDataContext(
           ^^^^^^^^^^^^^^^^
  File "/home/airflow/.local/lib/python3.12/site-packages/great_expectations/data_context/data_context/file_data_context.py", line 64, in __init__
    self._scaffold_project()
  File "/home/airflow/.local/lib/python3.12/site-packages/great_expectations/data_context/data_context/file_data_context.py", line 98, in _scaffold_project
    self._scaffold(
  File "/home/airflow/.local/lib/python3.12/site-packages/great_expectations/data_context/data_context/serializable_data_context.py", line 220, in _scaffold
    cls._scaffold_directories(gx_dir)
  File "/home/airflow/.local/lib/python3.12/site-packages/great_expectations/data_context/data_context/serializable_data_context.py", line 316, in _scaffold_directories
    cls._scaffold_custom_data_docs(plugins_dir)
  File "/home/airflow/.local/lib/python3.12/site-packages/great_expectations/data_context/data_context/serializable_data_context.py", line 351, in _scaffold_custom_data_docs
    shutil.copyfile(styles_template, styles_destination_path)
  File "/usr/local/lib/python3.12/shutil.py", line 262, in copyfile
    with open(dst, 'wb') as fdst:
         ^^^^^^^^^^^^^^^
PermissionError: [Errno 13] Permission denied: '/opt/airflow/gx/plugins/custom_data_docs/styles/data_docs_custom_styles.css'

During handling of the above exception, another exception occurred:

Traceback (most recent call last):
  File "/home/airflow/.local/lib/python3.12/site-packages/airflow/models/taskinstance.py", line 274, in _run_raw_task
    TaskInstance._execute_task_with_callbacks(
  File "/home/airflow/.local/lib/python3.12/site-packages/airflow/models/taskinstance.py", line 3161, in _execute_task_with_callbacks
    result = self._execute_task(context, task_orig)
             ^^^^^^^^^^^^^^^^^^^^^^^^^^^^^^^^^^^^^^
  File "/home/airflow/.local/lib/python3.12/site-packages/airflow/models/taskinstance.py", line 3185, in _execute_task
    return _execute_task(self, context, task_orig)
           ^^^^^^^^^^^^^^^^^^^^^^^^^^^^^^^^^^^^^^^
  File "/home/airflow/.local/lib/python3.12/site-packages/airflow/models/taskinstance.py", line 768, in _execute_task
    result = _execute_callable(context=context, **execute_callable_kwargs)
             ^^^^^^^^^^^^^^^^^^^^^^^^^^^^^^^^^^^^^^^^^^^^^^^^^^^^^^^^^^^^^
  File "/home/airflow/.local/lib/python3.12/site-packages/airflow/models/taskinstance.py", line 734, in _execute_callable
    return ExecutionCallableRunner(
           ^^^^^^^^^^^^^^^^^^^^^^^^
  File "/home/airflow/.local/lib/python3.12/site-packages/airflow/utils/operator_helpers.py", line 252, in run
    return self.func(*args, **kwargs)
           ^^^^^^^^^^^^^^^^^^^^^^^^^^
  File "/home/airflow/.local/lib/python3.12/site-packages/airflow/models/baseoperator.py", line 424, in wrapper
    return func(self, *args, **kwargs)
           ^^^^^^^^^^^^^^^^^^^^^^^^^^^
  File "/home/airflow/.local/lib/python3.12/site-packages/airflow/decorators/base.py", line 266, in execute
    return_value = super().execute(context)
                   ^^^^^^^^^^^^^^^^^^^^^^^^
  File "/home/airflow/.local/lib/python3.12/site-packages/airflow/models/baseoperator.py", line 424, in wrapper
    return func(self, *args, **kwargs)
           ^^^^^^^^^^^^^^^^^^^^^^^^^^^
  File "/home/airflow/.local/lib/python3.12/site-packages/airflow/operators/python.py", line 238, in execute
    return_value = self.execute_callable()
                   ^^^^^^^^^^^^^^^^^^^^^^^
  File "/home/airflow/.local/lib/python3.12/site-packages/airflow/operators/python.py", line 256, in execute_callable
    return runner.run(*self.op_args, **self.op_kwargs)
           ^^^^^^^^^^^^^^^^^^^^^^^^^^^^^^^^^^^^^^^^^^^
  File "/home/airflow/.local/lib/python3.12/site-packages/airflow/utils/operator_helpers.py", line 252, in run
    return self.func(*args, **kwargs)
           ^^^^^^^^^^^^^^^^^^^^^^^^^^
  File "/opt/airflow/dags/ingestion_pipeline.py", line 71, in validate_data
    raise AirflowFailException(f"Validation failed: {str(e)}")
airflow.exceptions.AirflowFailException: Validation failed: [Errno 13] Permission denied: '/opt/airflow/gx/plugins/custom_data_docs/styles/data_docs_custom_styles.css'

During handling of the above exception, another exception occurred:

Traceback (most recent call last):
  File "/home/airflow/.local/lib/python3.12/site-packages/sqlalchemy/engine/base.py", line 1910, in _execute_context
    self.dialect.do_execute(
  File "/home/airflow/.local/lib/python3.12/site-packages/sqlalchemy/engine/default.py", line 736, in do_execute
    cursor.execute(statement, parameters)
psycopg2.errors.ForeignKeyViolation: insert or update on table "task_fail" violates foreign key constraint "task_fail_ti_fkey"
DETAIL:  Key (dag_id, task_id, run_id, map_index)=(employee_ingestion_dag, validate_data, __airflow_temporary_run_2025-07-12T13:18:17.379808+00:00__, -1) is not present in table "task_instance".


The above exception was the direct cause of the following exception:

Traceback (most recent call last):
  File "/home/airflow/.local/lib/python3.12/site-packages/airflow/task/task_runner/standard_task_runner.py", line 117, in _start_by_fork
    ret = args.func(args, dag=self.dag)
          ^^^^^^^^^^^^^^^^^^^^^^^^^^^^^
  File "/home/airflow/.local/lib/python3.12/site-packages/airflow/cli/cli_config.py", line 49, in command
    return func(*args, **kwargs)
           ^^^^^^^^^^^^^^^^^^^^^
  File "/home/airflow/.local/lib/python3.12/site-packages/airflow/utils/cli.py", line 116, in wrapper
    return f(*args, **kwargs)
           ^^^^^^^^^^^^^^^^^^
  File "/home/airflow/.local/lib/python3.12/site-packages/airflow/cli/commands/task_command.py", line 483, in task_run
    task_return_code = _run_task_by_selected_method(args, _dag, ti)
                       ^^^^^^^^^^^^^^^^^^^^^^^^^^^^^^^^^^^^^^^^^^^^
  File "/home/airflow/.local/lib/python3.12/site-packages/airflow/cli/commands/task_command.py", line 256, in _run_task_by_selected_method
    return _run_raw_task(args, ti)
           ^^^^^^^^^^^^^^^^^^^^^^^
  File "/home/airflow/.local/lib/python3.12/site-packages/airflow/cli/commands/task_command.py", line 341, in _run_raw_task
    return ti._run_raw_task(
           ^^^^^^^^^^^^^^^^^
  File "/home/airflow/.local/lib/python3.12/site-packages/airflow/utils/session.py", line 97, in wrapper
    return func(*args, session=session, **kwargs)
           ^^^^^^^^^^^^^^^^^^^^^^^^^^^^^^^^^^^^^^
  File "/home/airflow/.local/lib/python3.12/site-packages/airflow/models/taskinstance.py", line 3006, in _run_raw_task
    return _run_raw_task(
           ^^^^^^^^^^^^^^
  File "/home/airflow/.local/lib/python3.12/site-packages/airflow/models/taskinstance.py", line 315, in _run_raw_task
    ti.handle_failure(e, test_mode, context, force_fail=True, session=session)  # already saves to db
    ^^^^^^^^^^^^^^^^^^^^^^^^^^^^^^^^^^^^^^^^^^^^^^^^^^^^^^^^^^^^^^^^^^^^^^^^^^
  File "/home/airflow/.local/lib/python3.12/site-packages/airflow/utils/session.py", line 94, in wrapper
    return func(*args, **kwargs)
           ^^^^^^^^^^^^^^^^^^^^^
  File "/home/airflow/.local/lib/python3.12/site-packages/airflow/models/taskinstance.py", line 3434, in handle_failure
    _handle_failure(
  File "/home/airflow/.local/lib/python3.12/site-packages/airflow/utils/session.py", line 94, in wrapper
    return func(*args, **kwargs)
           ^^^^^^^^^^^^^^^^^^^^^
  File "/home/airflow/.local/lib/python3.12/site-packages/airflow/api_internal/internal_api_call.py", line 166, in wrapper
    return func(*args, **kwargs)
           ^^^^^^^^^^^^^^^^^^^^^
  File "/home/airflow/.local/lib/python3.12/site-packages/airflow/models/taskinstance.py", line 1244, in _handle_failure
    TaskInstance.save_to_db(task_instance, session)
  File "/home/airflow/.local/lib/python3.12/site-packages/airflow/api_internal/internal_api_call.py", line 166, in wrapper
    return func(*args, **kwargs)
           ^^^^^^^^^^^^^^^^^^^^^
  File "/home/airflow/.local/lib/python3.12/site-packages/airflow/utils/session.py", line 94, in wrapper
    return func(*args, **kwargs)
           ^^^^^^^^^^^^^^^^^^^^^
  File "/home/airflow/.local/lib/python3.12/site-packages/airflow/models/taskinstance.py", line 3402, in save_to_db
    ti.get_dagrun().refresh_from_db()
    ^^^^^^^^^^^^^^^
  File "/home/airflow/.local/lib/python3.12/site-packages/airflow/utils/session.py", line 96, in wrapper
    with create_session() as session:
         ^^^^^^^^^^^^^^^^
  File "/usr/local/lib/python3.12/contextlib.py", line 144, in __exit__
    next(self.gen)
  File "/home/airflow/.local/lib/python3.12/site-packages/airflow/utils/session.py", line 57, in create_session
    session.commit()
  File "/home/airflow/.local/lib/python3.12/site-packages/sqlalchemy/orm/session.py", line 1454, in commit
    self._transaction.commit(_to_root=self.future)
  File "/home/airflow/.local/lib/python3.12/site-packages/sqlalchemy/orm/session.py", line 832, in commit
    self._prepare_impl()
  File "/home/airflow/.local/lib/python3.12/site-packages/sqlalchemy/orm/session.py", line 811, in _prepare_impl
    self.session.flush()
  File "/home/airflow/.local/lib/python3.12/site-packages/sqlalchemy/orm/session.py", line 3449, in flush
    self._flush(objects)
  File "/home/airflow/.local/lib/python3.12/site-packages/sqlalchemy/orm/session.py", line 3588, in _flush
    with util.safe_reraise():
         ^^^^^^^^^^^^^^^^^^^
  File "/home/airflow/.local/lib/python3.12/site-packages/sqlalchemy/util/langhelpers.py", line 70, in __exit__
    compat.raise_(
  File "/home/airflow/.local/lib/python3.12/site-packages/sqlalchemy/util/compat.py", line 211, in raise_
    raise exception
  File "/home/airflow/.local/lib/python3.12/site-packages/sqlalchemy/orm/session.py", line 3549, in _flush
    flush_context.execute()
  File "/home/airflow/.local/lib/python3.12/site-packages/sqlalchemy/orm/unitofwork.py", line 456, in execute
    rec.execute(self)
  File "/home/airflow/.local/lib/python3.12/site-packages/sqlalchemy/orm/unitofwork.py", line 630, in execute
    util.preloaded.orm_persistence.save_obj(
  File "/home/airflow/.local/lib/python3.12/site-packages/sqlalchemy/orm/persistence.py", line 245, in save_obj
    _emit_insert_statements(
  File "/home/airflow/.local/lib/python3.12/site-packages/sqlalchemy/orm/persistence.py", line 1238, in _emit_insert_statements
    result = connection._execute_20(
             ^^^^^^^^^^^^^^^^^^^^^^^
  File "/home/airflow/.local/lib/python3.12/site-packages/sqlalchemy/engine/base.py", line 1710, in _execute_20
    return meth(self, args_10style, kwargs_10style, execution_options)
           ^^^^^^^^^^^^^^^^^^^^^^^^^^^^^^^^^^^^^^^^^^^^^^^^^^^^^^^^^^^
  File "/home/airflow/.local/lib/python3.12/site-packages/sqlalchemy/sql/elements.py", line 334, in _execute_on_connection
    return connection._execute_clauseelement(
           ^^^^^^^^^^^^^^^^^^^^^^^^^^^^^^^^^^
  File "/home/airflow/.local/lib/python3.12/site-packages/sqlalchemy/engine/base.py", line 1577, in _execute_clauseelement
    ret = self._execute_context(
          ^^^^^^^^^^^^^^^^^^^^^^
  File "/home/airflow/.local/lib/python3.12/site-packages/sqlalchemy/engine/base.py", line 1953, in _execute_context
    self._handle_dbapi_exception(
  File "/home/airflow/.local/lib/python3.12/site-packages/sqlalchemy/engine/base.py", line 2134, in _handle_dbapi_exception
    util.raise_(
  File "/home/airflow/.local/lib/python3.12/site-packages/sqlalchemy/util/compat.py", line 211, in raise_
    raise exception
  File "/home/airflow/.local/lib/python3.12/site-packages/sqlalchemy/engine/base.py", line 1910, in _execute_context
    self.dialect.do_execute(
  File "/home/airflow/.local/lib/python3.12/site-packages/sqlalchemy/engine/default.py", line 736, in do_execute
    cursor.execute(statement, parameters)
sqlalchemy.exc.IntegrityError: (psycopg2.errors.ForeignKeyViolation) insert or update on table "task_fail" violates foreign key constraint "task_fail_ti_fkey"
DETAIL:  Key (dag_id, task_id, run_id, map_index)=(employee_ingestion_dag, validate_data, __airflow_temporary_run_2025-07-12T13:18:17.379808+00:00__, -1) is not present in table "task_instance".

[SQL: INSERT INTO task_fail (task_id, dag_id, run_id, map_index, start_date, end_date, duration) VALUES (%(task_id)s, %(dag_id)s, %(run_id)s, %(map_index)s, %(start_date)s, %(end_date)s, %(duration)s) RETURNING task_fail.id]
[parameters: {'task_id': 'validate_data', 'dag_id': 'employee_ingestion_dag', 'run_id': '__airflow_temporary_run_2025-07-12T13:18:17.379808+00:00__', 'map_index': -1, 'start_date': datetime.datetime(2025, 7, 12, 13, 18, 19, 377418, tzinfo=Timezone('UTC')), 'end_date': datetime.datetime(2025, 7, 12, 13, 18, 22, 155373, tzinfo=Timezone('UTC')), 'duration': 2}]
(Background on this error at: https://sqlalche.me/e/14/gkpj)
[2025-07-12T13:18:22.229+0000] {local_task_job_runner.py:266} INFO - Task exited with return code 1
[2025-07-12T13:18:22.241+0000] {local_task_job_runner.py:245} INFO - ::endgroup::
